## 진행코드
all_title = all_files_data_concat['제목']

all_title

### 오류
NameError                                 Traceback (most recent call last)
Cell In[2], line 1
----> 1 all_title = all_files_data_concat['제목']
      3 all_title

NameError: name 'all_files_data_concat' is not defined

## 직접 다운받은 빅데이터 파일의 형식이 변경 -> 
## 컬럼을 제목에서 참고문헌양식으로 변환 후 재실행


### 진행코드
ll_files_data_concat['doc_count'] = 0
summary_year = all_files_data_concat.groupby('출판일', as_index=False)['doc_count'].count()
summary_year

### 오류
KeyError                                  Traceback (most recent call last)
Cell In[25], line 2
      1 all_files_data_concat['doc_count'] = 0
----> 2 summary_year = all_files_data_concat.groupby('출판일', as_index=False)['doc_count'].count()
      3 summary_year

File C:\ProgramData\anaconda3\Lib\site-packages\pandas\core\frame.py:8869, in DataFrame.groupby(self, by, axis, level, as_index, sort, group_keys, observed, dropna)
   8866 if level is None and by is None:
   8867     raise TypeError("You have to supply one of 'by' and 'level'")
-> 8869 return DataFrameGroupBy(
   8870     obj=self,
   8871     keys=by,
   8872     axis=axis,
   8873     level=level,
   8874     as_index=as_index,
   8875     sort=sort,
   8876     group_keys=group_keys,
   8877     observed=observed,
   8878     dropna=dropna,
   8879 )

File C:\ProgramData\anaconda3\Lib\site-packages\pandas\core\groupby\groupby.py:1278, in GroupBy.__init__(self, obj, keys, axis, level, grouper, exclusions, selection, as_index, sort, group_keys, observed, dropna)
   1275 self.dropna = dropna
   1277 if grouper is None:
-> 1278     grouper, exclusions, obj = get_grouper(
   1279         obj,
   1280         keys,
   1281         axis=axis,
   1282         level=level,
   1283         sort=sort,
   1284         observed=False if observed is lib.no_default else observed,
   1285         dropna=self.dropna,
   1286     )
   1288 if observed is lib.no_default:
   1289     if any(ping._passed_categorical for ping in grouper.groupings):

File C:\ProgramData\anaconda3\Lib\site-packages\pandas\core\groupby\grouper.py:1009, in get_grouper(obj, key, axis, level, sort, observed, validate, dropna)
   1007         in_axis, level, gpr = False, gpr, None
   1008     else:
-> 1009         raise KeyError(gpr)
   1010 elif isinstance(gpr, Grouper) and gpr.key is not None:
   1011     # Add key to exclusions
   1012     exclusions.add(gpr.key)

KeyError: '출판일'

## 마찬가지로 변환된 데이터프레임형식으로 인해 출판일 이라는 프레임 존재 x
## 이건 어쩔 수 없이 예전 자료로 해당부분만 재실습 진행





## 코드
word_count['big'] = word_count_backup['big']
word_count['data'] = word_count_backup['data']


## 오류
NameError                                 Traceback (most recent call last)
Cell In[28], line 1
----> 1 word_count['big'] = word_count_backup['big']
      2 word_count['data'] = word_count_backup['data']

NameError: name 'word_count_backup' is not defined

## del로 지워버린 big과 data의 워드클라우드도 보고싶어 진행, 백업데이터를 저장하지 않았다는것을 알았음
## 자료를 다시 불러오는 것으로 해결


##진행코드
del word_count['knowledge']
del word_count['ieee']
del word_count['transaction']
del word_count['journal']

##오류
NameError                                 Traceback (most recent call last)
Cell In[6], line 1
----> 1 del word_count['knowledge']
      2 del word_count['ieee']
      3 del word_count['transaction']

NameError: name 'word_count' is not defined


## 다른 워드도 지워서 확인을 해보고 싶었지만 오류발생
## 원인을 찾아보니 중간에 파일위치와 주피터 노트북을 한번 껏다 켜서 발생한것으로 확인 
## 예제 데이터로 재실습할 때 확인해보기로 함